Workbook

Sheet Estado de Situación Financiera
B2: ESTADO DE SITUACIÓN FINANCIERA
B3: FRANCOCERAMICAS SAS
B4: NIT.: 901822884
B5: Al 31 de diciembre de 2025
B6: Cifras expresadas en pesos colombianos (COP)
B8: CONCEPTO | J8: 2025
B10: A C T I V O S
B12: ACTIVO CORRIENTE
B13: Efectivo y equivalentes de efectivo | J13: =10186953-119332.68+6500 -> 10074120
B14: Inversiones temporales | J14: 0
B15: Cuentas por cobrar clientes | J15: =40002047 -> 40002047
B16: Provisión cartera de dudoso recaudo | J16: 0
B17: Otras cuentas por cobrar | J17: 81253000
B18: Inventarios | J18: =296511694-66078964.92 -> 2.3043273e+08
B19: Gastos pagados por anticipado | J19: 0
B20: Otros activos corrientes | J20: 20000000
B21: TOTAL ACTIVO CORRIENTE | J21: =SUM(J13:J20) -> 3.817619e+08
B23: ACTIVO NO CORRIENTE
B24: Inversiones en subsidiarias y asociadas | J24: 0
B25: Propiedades, planta y equipo — bruto | J25: 16218754
B26: Depreciación acumulada | J26: -2243750.4
B27: Activos intangibles — neto | J27: 0
B28: Propiedades de inversión | J28: 0
B29: Otros activos no corrientes | J29: 0
B30: TOTAL ACTIVO NO CORRIENTE | J30: =SUM(J24:J29) -> 13975004
B32: TOTAL ACTIVO | J32: =J21+J30 -> 395736900
B34: P A S I V O S
B36: PASIVO CORRIENTE
B37: Obligaciones financieras corto plazo | J37: 0
B38: Cuentas por pagar proveedores | J38: 1.2375119e+08
B39: Costos y gastos por pagar | J39: 0
B40: Impuestos por pagar | J40: 0
B41: Obligaciones laborales | J41: =5420000-1253000 -> 4167000
B42: Ingresos recibidos por anticipado | J42: 27000000
B43: Otros pasivos corrientes | J43: 0
B44: TOTAL PASIVO CORRIENTE | J44: =SUM(J37:J43) -> 1.5491819e+08
B46: PASIVO NO CORRIENTE
B47: Obligaciones financieras largo plazo | J47: 0
B48: Pasivos por impuesto diferido | J48: 0
B49: Beneficios a empleados largo plazo | J49: 0
...

Sheet Estado de Resultados
B2: ESTADO DE RESULTADOS INTEGRAL
B3: =+'Estado de Situación Financiera'!B3 -> FRANCOCERAMICAS SAS
B4: =+'Estado de Situación Financiera'!B4 -> NIT.: 901822884
B5: Por el período comprendido entre el 1 de enero y el 31 de diciembre de 2025
B6: Cifras expresadas en pesos colombianos (COP)
B8: CONCEPTO | H8: 2025
B10: INGRESOS OPERACIONALES
B11: Ventas brutas de mercancía | H11: 2.2304648e+08
B12: Devoluciones y descuentos | H12: -8578816.9
B13: VENTAS NETAS | H13: =H11+H12 -> 2.1446767e+08
B15: COSTO DE VENTAS
B16: Inventario inicial | H16: -99105508
B17: Compras netas del período | H17: 0
B18: Mercancía disponible para venta | H18: =H16+H17 -> -99105508
B19: Inventario final | H19: 0
B20: COSTO DE VENTAS | H20: =H18+H19 -> -99105508
B22: UTILIDAD BRUTA | H22: =H13+H20 -> 1.1536216e+08
B24: GASTOS OPERACIONALES DE ADMINISTRACIÓN
B25: Gastos de personal administrativo | H25: -36556102
B26: Honorarios | H26: -4500000
B27: Arrendamientos | H27: -18000000
B28: Seguros | H28: 0
B29: Servicios públicos | H29: -3560000
B30: Mantenimiento y reparaciones | H30: 0
B31: Depreciaciones y amortizaciones | H31: =+'Estado de Situación Financiera'!J26 -> -2243750.4
B32: Gastos de administración varios | H32: 0
B33: TOTAL GASTOS ADMINISTRACIÓN | H33: =SUM(H25:H32) -> -64859852
B35: GASTOS OPERACIONALES DE VENTAS
B36: Gastos de personal de ventas | H36: 0
B37: Comisiones y honorarios de ventas | H37: 0
B38: Publicidad y marketing | H38: =-9121888.067333-59852.27 -> -9181740.3
B39: Transporte y logística | H39: 0
B40: Gastos de ventas varios | H40: 0
B41: TOTAL GASTOS DE VENTAS | H41: =SUM(H36:H40) -> -9181740.3
B43: TOTAL GASTOS OPERACIONALES | H43: =H33+H41 -> -74041593
B45: UTILIDAD OPERACIONAL (EBIT) | H45: =H22+H43 -> 41320565
B47: INGRESOS NO OPERACIONALES
B48: Ingresos financieros | H48: 0
B49: Rendimientos e inversiones | H49: 0
B50: Otros ingresos no operacionales | H50: 0
...

Sheet Calculadora
B3: Indicadores de capacidad financiera | G3: Datos financieros (Estados financieros)
B4: Indicadores de capacidad financiera | C4: Francoceramicas | D4: Nivel optimo | E4: Cumple / No cumple | G4: Activo Corriente | H4: =+'Estado de Situación Financiera'!J21 -> 3.817619e+08
B5: Liquidez: Activo Corriente / Pasivo Corriente | C5: =H4/H5 -> 2.4642807 | D5: 2 | E5: =IF(C5>=D5,"CUMPLE","NO CUMPLE") -> CUMPLE | G5: Pasivo Corriente | H5: =+'Estado de Situación Financiera'!J44 -> 1.5491819e+08
B6: Endeudamiento: Pasivo Total / Activo Total | C6: =H7/H6 -> 0.5978088 | D6: 0.4 | E6: =IF(C6>=D6,"NO CUMPLE","CUMPLE") -> NO CUMPLE | G6: Activo Total | H6: =+'Estado de Situación Financiera'!J32 -> 395736900
B7: Razón de Cobertura de Intereses = Utilidad Operacional / Gastos de Intereses | C7: =H9/H10 -> 17.400577 | D7: 14 | E7: =IF(C7<=D7,"NO CUMPLE","CUMPLE") -> CUMPLE | G7: Pasivo Total | H7: =+'Estado de Situación Financiera'!J53 -> 2.36575e+08
B8: Rentabilidad del patrimonio: Utilidad Operacional / Patrimonio | C8: =H9/H8 -> 0.25961342 | D8: 0.14 | E8: =IF(C8>=D8,"CUMPLE","NO CUMPLE") -> CUMPLE | G8: Patrimonio | H8: =+'Estado de Situación Financiera'!J65 -> 1.591619e+08
B9: Rentabilidad sobre activos: Utilidad Operacional / Activo Total | C9: =H9/H6 -> 0.10441423 | D9: 0.14 | E9: =IF(C9>=D9,"CUMPLE","NO CUMPLE") -> NO CUMPLE | G9: Utilidad Operacional | H9: =+'Estado de Resultados'!H45 -> 41320565
B10: KT Capital de trabajo: (Activo corriente - Pasivo) | C10: =+(H4-H5) -> 2.2684371e+08 | E10: =IF(C10>=D10,"CUMPLE","NO CUMPLE") -> CUMPLE | G10: Gastos de Intereses | H10: =-'Estado de Resultados'!H54 -> 2374666.4
