Workbook
Name AC: #REF!
Name AC: #REF!
Name AC: #REF!
Name ACC: #REF!
Name ACC: #REF!
Name actividades_tarifas: '[1]Actividades '!$B$12:$J$40
Name AD: #REF!
Name AD: #REF!
Name Año_1: #REF!
Name Año_1: #REF!
Name Año_2: #REF!
Name Año_2: #REF!
Name AOP: #REF!
Name ARL: [2]Tablas!$A$12:$B$17
Name AS: #REF!
Name AS: #REF!
Name AS: #REF!
Name BE: #REF!
Name BE: #REF!
Name Bimestralmente: #REF!
Name Bimestralmente: #REF!
Name BP_APERTURA: #REF!
Name BP_Diciembre_Año_2: #REF!
Name BP_Enero_Año_1: #REF!
Name CIR: #REF!
Name Codigo_Ctro_Costos_Grupo: #REF!
Name Codigo_CtroCostos: #REF!
Name Codigo1: [3]Año_1!$A$1:$A$65536
Name Codigos_PUC: #REF!
Name Codigos_PUC: #REF!
Name Codigos_PUC: #REF!
Name CR: #REF!
Name CR: #REF!
Name Cuatrimestralmente: #REF!
Name Cuatrimestralmente: #REF!
Name CV: #REF!
Name DC: #REF!
Name DII: [4]Normativa!$E$46:$F$55
Name DIP: [4]Normativa!$M$20:$N$29
Name ECP: #REF!
Name ECP: #REF!
Name ECP: #REF!
Name ECPC: #REF!
Name ECPC: #REF!
Name EFE: #REF!
Name EFE: #REF!
Name EGC: [4]Normativa!$N$162:$O$171
Name ENGC: [4]Normativa!$J$162:$K$261
Name ERC: #REF!
Name ERC: #REF!
Name ERC: #REF!
Name ETC: #REF!
Name ETC: #REF!
Name EYE: #REF!
Name EYE: #REF!
Name GCI: [4]Normativa!$E$33:$F$42
Name GCII: [4]Normativa!$I$33:$J$42
Name GCIII: [4]Normativa!$M$33:$N$42
Name GIMP: #REF!
Name GIMP: #REF!

Sheet Copyright
E9: x
B17: https://actualicese.com/caso-practico-de-presupuestos-y-proyecciones-financieras-para-una-pyme/

Sheet Empieza aquí
E8: x

Sheet Introducción
B3: Caso práctico de presupuestos y proyecciones financieras para una pyme
B5: (Fecha de elaboración: enero 30 de 2025)
B7: Aquí encontrarás un ejemplo de los presupuestos de ventas, producción, mano de obra, costos de fabricación, cartera, inversión y más herramientas que te ayudarán en la proyección organizacional de una pyme.
B8: La preparación del presupuesto no solo corresponde a un único momento del año, sino que es necesario realizarle un seguimiento constante para que funcione eficientemente.
B9: Recuerda que como profesional contable no solo elaboras y auditas información financiera, también analizas y reflexionas críticamente, convirtiéndote en un aliado clave para la toma de decisiones estratégicas dentro de las empresas que asesoras.
B10: La importancia de los presupuestos en las organizaciones
B11: El diseño de los presupuestos hace parte de la planeación de las operaciones y el destino de los recursos de una compañía. Es una formulación anticipada de los ingresos, costos y la producción de las empresas, de modo que se pueda garantizar la liquidez y el mantenimiento del capital de trabajo.
B12: Esta herramienta es una de las formas más sencillas de tener un control futuro sobre las operaciones del negocio. Sin embargo, en las pequeñas y medianas empresas se ha dificultado ampliamente la construcción e implementación del presupuesto, debido a que requiere de tiempo y compromiso por parte de la entidad y de quien lo elabora.
B13: El presupuesto es el punto de partida para estimar los indicadores de las entidades y permite que los administradores y socios tomen decisiones oportunas basadas en datos reales, de allí su importancia.
B14: =+B3 -> Caso práctico de presupuestos y proyecciones financieras para una pyme
B15: Como ya lo vimos, uno de los principales objetivos de los presupuestos es optimizar el uso de los recursos, ya que con este se tiene en claro la cantidad de dinero que ingresa a la empresa, si alcanza para cubrir los gastos, si queda para ahorrar o si existe la necesidad de buscar nuevas fuentes de financiación. Sin embargo, muchas personas no saben cómo construirlo y cuál es el propósito de registrar el día a día de lo que ganamos y gastamos.
B16: Teniendo en cuenta lo anterior, hemos desarrollado este caso práctico con el cual podrás identificar los rubros más importantes que se mueven durante el año en una pyme, para luego agruparlos según su importancia y periodicidad. Partiendo de la hoja "Datos base" conocerás el paso a paso para diseñar el estado de costos, estado de resultados, flujo de caja y estado de situación financiera, cuyas cifras provienen de los diferentes presupuestos que te enseñaremos a elaborar.
B17: ¡Eleva tu nivel profesional! Te invitamos a resolver el siguiente cuestionario: ¿Qué tan actualizado te sientes sobre planeación tributaria para el impuesto de renta?
B18: Nota: el diseño, los datos o comentarios bajo los cuales se elaboró este formato y cada una de sus hojas de cálculo se entregan a título de guía y hacen parte de la interpretación de Actualícese. Será el usuario quien deba estudiar las normas requeridas, preparar y emitir la información a la que haya lugar. Actualícese no se hace responsable de las interpretaciones, operaciones o información derivadas del uso de esta herramienta.
B20: Material relacionado:
B21: [Especial Actualícese] Presupuestos: así se clasifican y definen
B22: A partir de los pronósticos construidos con los datos históricos de las empresas, los presupuestos constituyen el análisis del presente y del futuro de las organizaciones. Te presentamos la definición y la clasificación de los presupuestos, dada su importancia en la toma de decisiones.
B23: [Lista de chequeo] Evaluación de las 4 fases de la planeación tributaria del impuesto de renta
B24: En esta lista de chequeo encontrarás más de 100 actividades que recomendamos evaluar para llevar a cabo satisfactoriamente una planeación tributaria. Se encuentra dividida en 4 fases: conocimiento del negocio, estado actual de las obligaciones, identificación de oportunidades y elaboración del plan de acción.
B25: [Guía Actualícese] Planeación financiera del diagnóstico a la estrategia en 5 pasos
B26: Domina la planeación financiera en tu empresa, aprende a analizar tu entorno, diagnosticar fortalezas y debilidades, crear estrategias adaptadas a tus objetivos y proyectar resultados con herramientas prácticas. Anticípate a los cambios, minimiza riesgos y asegura el crecimiento sostenible de tu organización.

Sheet Datos base
B3: Datos iniciales
B5: Producto | C5: Unidades para vender en 2025 | D5: Precio unitario
B6: Sala | C6: 67 | D6: 1800000
B7: Comedor | C7: 50 | D7: 1300000
B8: Alcoba | C8: 40 | D8: 1650000
B9: Poltrona | C9: 32 | D9: 930000
B10: Sofacama | C10: 25 | D10: 1100000
B12: Concepto | F12: Valor
B13: Incremento de unidades a vender por año | F13: 0.1
B14: Incremento de elementos de materia prima requeridos para la producción | F14: 0.1
B15: Días de inventario final de producto terminado | F15: 5
B16: Días de inventario final de materia prima | F16: 5
B17: Política de cobro de cartera en días | F17: 15
B18: Porcentaje de ventas a crédito | F18: 0.6
B19: Porcentaje de ventas a contado | F19: =1-F18 -> 0.4
B20: Aportes de socios | F20: 155000000
B21: Costo de la obligación financiera | F21: 0.25
B22: Tarifa de impuesto de renta | F22: 0.35
B23: Reserva legal | F23: 0.1
B24: Política de pago a proveedores en días | F24: 30
B26: Considerando que las unidades a vender por año incrementarán un 10 %, los elementos de materia prima requeridos para la producción también incrementarán un 10 % anual.
B28: Se entiende que al cierre del año no hay inventario inicial ni final de producto en proceso.
B30: Para efectos prácticos se determina el impuesto de renta sobre la utilidad antes de impuesto, no obstante, lo adecuado sería realizarlo a partir de la depuración contable y fiscal.
C32: 2025 | D32: 2026 | E32: 2027 | F32: 2028 | G32: 2029
B33: Inflación | C33: 0.043 | D33: 0.039 | E33: 0.037 | F33: 0.036 | G33: 0.035
B34: Salario básico | C34: 1423500 | D34: =C34*(1+D33) -> 1479016.5 | E34: =D34*(1+E33) -> 1533740.1 | F34: =E34*(1+F33) -> 1588954.8 | G34: =F34*(1+G33) -> 1644568.2
B35: Auxilio de transporte | C35: 200000 | D35: =C35*(1+D33) -> 207800 | E35: =D35*(1+E33) -> 215488.6 | F35: =E35*(1+F33) -> 223246.19 | G35: =F35*(1+G33) -> 231059.81
B37: Para la inflación se tienen en cuenta los datos contemplados en:
B38: Guía 2025 de la Dirección de investigaciones económicas, sectoriales y de mercado del grupo Bancolombia
B39: Informe de política monetaria - octubre de 2024 del Banco de la República
B41: Para el salario básico y el auxilio de transporte del año 2026 y siguientes se considera el incremento conforme a la inflación.
B43: Prestaciones sociales y seguridad social | E43: Factor
B44: Cesantías | E44: =30/360 -> 0.083333333
B45: Intereses de cesantías anual | E45: 0.12
B46: Prima de servicios | E46: =30/360 -> 0.083333333
B47: Vacaciones | E47: =15/360 -> 0.041666667
B48: Salud | E48: 0.085
B49: Pensión | E49: 0.12
B50: Caja de compensación familiar | E50: 0.04
B51: ARL producción | E51: 0.02436
...

Sheet Ppto Ventas
B3: Datos para elaborar el presupuesto de ventas
B5: Producto | C5: Unidades para vender en 2025 | D5: Precio unitario
B6: =+'Datos base'!B6 -> Sala | C6: ='Datos base'!C6 -> 67 | D6: ='Datos base'!D6 -> 1800000
B7: =+'Datos base'!B7 -> Comedor | C7: ='Datos base'!C7 -> 50 | D7: ='Datos base'!D7 -> 1300000
B8: =+'Datos base'!B8 -> Alcoba | C8: ='Datos base'!C8 -> 40 | D8: ='Datos base'!D8 -> 1650000
B9: =+'Datos base'!B9 -> Poltrona | C9: ='Datos base'!C9 -> 32 | D9: ='Datos base'!D9 -> 930000
B10: =+'Datos base'!B10 -> Sofacama | C10: ='Datos base'!C10 -> 25 | D10: ='Datos base'!D10 -> 1100000
B12: Incremento de unidades a vender por año: | F12: =+'Datos base'!F13 -> 0.1
C14: 2025 | D14: 2026 | E14: 2027 | F14: 2028 | G14: 2029
B15: Inflación | C15: ='Datos base'!C33 -> 0.043 | D15: ='Datos base'!D33 -> 0.039 | E15: ='Datos base'!E33 -> 0.037 | F15: ='Datos base'!F33 -> 0.036 | G15: ='Datos base'!G33 -> 0.035
B17: Elaboración del presupuesto de ventas
B19: Presupuesto de ventas
B20: Producto | C20: Concepto | D20: 2025 | E20: 2026 | F20: 2027 | G20: 2028 | H20: 2029
B21: =+B6 -> Sala | C21: Unidad | D21: =C6 -> 67 | E21: =ROUNDUP(D21*(1+$F$12),0) -> 74 | F21: =ROUNDUP(E21*(1+$F$12),0) -> 82 | G21: =ROUNDUP(F21*(1+$F$12),0) -> 91 | H21: =ROUNDUP(G21*(1+$F$12),0) -> 101
C22: Precio unitario | D22: =D6 -> 1800000 | E22: =D22*(1+$D$15) -> 1870200 | F22: =E22*(1+$E$15) -> 1939397.4 | G22: =F22*(1+$F$15) -> 2009215.7 | H22: =G22*(1+$G$15) -> 2079538.3
C23: Valor total | D23: =D21*D22 -> 120600000 | E23: =E21*E22 -> 1.383948e+08 | F23: =F21*F22 -> 1.5903059e+08 | G23: =G21*G22 -> 1.8283863e+08 | H23: =H21*H22 -> 2.1003336e+08
B24: =+B7 -> Comedor | C24: Unidad | D24: =C7 -> 50 | E24: =ROUNDUP(D24*(1+$F$12),0) -> 55 | F24: =ROUNDUP(E24*(1+$F$12),0) -> 61 | G24: =ROUNDUP(F24*(1+$F$12),0) -> 68 | H24: =ROUNDUP(G24*(1+$F$12),0) -> 75
C25: Precio unitario | D25: =D7 -> 1300000 | E25: =D25*(1+$D$15) -> 1350700 | F25: =E25*(1+$E$15) -> 1400675.9 | G25: =F25*(1+$F$15) -> 1451100.2 | H25: =G25*(1+$G$15) -> 1501888.7
C26: Valor total | D26: =D24*D25 -> 65000000 | E26: =E24*E25 -> 74288500 | F26: =F24*F25 -> 85441230 | G26: =G24*G25 -> 98674816 | H26: =H24*H25 -> 1.1264166e+08
B27: =+B8 -> Alcoba | C27: Unidad | D27: =C8 -> 40 | E27: =ROUNDUP(D27*(1+$F$12),0) -> 44 | F27: =ROUNDUP(E27*(1+$F$12),0) -> 49 | G27: =ROUNDUP(F27*(1+$F$12),0) -> 54 | H27: =ROUNDUP(G27*(1+$F$12),0) -> 60
C28: Precio unitario | D28: =D8 -> 1650000 | E28: =D28*(1+$D$15) -> 1714350 | F28: =E28*(1+$E$15) -> 1777780.9 | G28: =F28*(1+$F$15) -> 1841781.1 | H28: =G28*(1+$G$15) -> 1906243.4
C29: Valor total | D29: =D27*D28 -> 66000000 | E29: =E27*E28 -> 75431400 | F29: =F27*F28 -> 87111267 | G29: =G27*G28 -> 99456177 | H29: =H27*H28 -> 1.143746e+08
B30: =+B9 -> Poltrona | C30: Unidad | D30: =C9 -> 32 | E30: =ROUNDUP(D30*(1+$F$12),0) -> 36 | F30: =ROUNDUP(E30*(1+$F$12),0) -> 40 | G30: =ROUNDUP(F30*(1+$F$12),0) -> 44 | H30: =ROUNDUP(G30*(1+$F$12),0) -> 49
C31: Precio unitario | D31: =D9 -> 930000 | E31: =D31*(1+$D$15) -> 966270 | F31: =E31*(1+$E$15) -> 1002022 | G31: =F31*(1+$F$15) -> 1038094.8 | H31: =G31*(1+$G$15) -> 1074428.1
C32: Valor total | D32: =D30*D31 -> 29760000 | E32: =E30*E31 -> 34785720 | F32: =F30*F31 -> 40080880 | G32: =G30*G31 -> 45676170 | H32: =H30*H31 -> 52646977
B33: =+B10 -> Sofacama | C33: Unidad | D33: =C10 -> 25 | E33: =ROUNDUP(D33*(1+$F$12),0) -> 28 | F33: =ROUNDUP(E33*(1+$F$12),0) -> 31 | G33: =ROUNDUP(F33*(1+$F$12),0) -> 35 | H33: =ROUNDUP(G33*(1+$F$12),0) -> 39
C34: Precio unitario | D34: =D10 -> 1100000 | E34: =D34*(1+$D$15) -> 1142900 | F34: =E34*(1+$E$15) -> 1185187.3 | G34: =F34*(1+$F$15) -> 1227854 | H34: =G34*(1+$G$15) -> 1270828.9
C35: Valor total | D35: =D33*D34 -> 27500000 | E35: =E33*E34 -> 32001200 | F35: =F33*F34 -> 36740806 | G35: =G33*G34 -> 42974891 | H35: =H33*H34 -> 49562328
B36: Unidades totales | D36: =D21+D24+D27+D30+D33 -> 214 | E36: =E21+E24+E27+E30+E33 -> 237 | F36: =F21+F24+F27+F30+F33 -> 263 | G36: =G21+G24+G27+G30+G33 -> 292 | H36: =H21+H24+H27+H30+H33 -> 324 | J36: Insumo para el presupuesto de producción
B37: Valor total | D37: =D23+D26+D29+D32+D35 -> 308860000 | E37: =E23+E26+E29+E32+E35 -> 3.5490162e+08 | F37: =F23+F26+F29+F32+F35 -> 4.0840477e+08 | G37: =G23+G26+G29+G32+G35 -> 4.6962068e+08 | H37: =H23+H26+H29+H32+H35 -> 5.3925893e+08 | J37: Insumo para el presupuesto de cartera, estado de resultados y el flujo de caja

Sheet Ppto Producción
B3: Datos para elaborar el presupuesto de producción
C6: 2025 | D6: 2026 | E6: 2027 | F6: 2028 | G6: 2029
B7: Inflación | C7: ='Datos base'!C33 -> 0.043 | D7: ='Datos base'!D33 -> 0.039 | E7: ='Datos base'!E33 -> 0.037 | F7: ='Datos base'!F33 -> 0.036 | G7: ='Datos base'!G33 -> 0.035
B9: Días de inventario final de producto terminado | E9: ='Datos base'!F15 -> 5
B10: Días de inventario final de materia prima | E10: ='Datos base'!F16 -> 5
B12: Considerando que las unidades a vender por año incrementarán un 10 %, los elementos de materia prima requeridos para la producción también incrementarán un 10 % anual.
B13: Se considera que al cierre de año no hay inventario inicial ni final de producto en proceso.
B15: Incremento de elementos de materia prima requeridos para la producción | E15: ='Datos base'!F14 -> 0.1
B17: Elaboración del presupuesto de producción
B19: Unidades a producir
B20: Concepto | C20: 2025 | D20: 2026 | E20: 2027 | F20: 2028 | G20: 2029
B21: Unidades a vender | C21: ='Ppto Ventas'!D36 -> 214 | D21: ='Ppto Ventas'!E36 -> 237 | E21: ='Ppto Ventas'!F36 -> 263 | F21: ='Ppto Ventas'!G36 -> 292 | G21: ='Ppto Ventas'!H36 -> 324 | I21: Valores tomados del presupuesto de ventas
B22: + Inventario final producto terminado | C22: =ROUNDUP((C21/360)*$E$9,0) -> 3 | D22: =ROUNDUP((D21/360)*$E$9,0) -> 4 | E22: =ROUNDUP((E21/360)*$E$9,0) -> 4 | F22: =ROUNDUP((F21/360)*$E$9,0) -> 5 | G22: =ROUNDUP((G21/360)*$E$9,0) -> 5
B23: - Inventario inicial producto terminado | C23: 0 | D23: =C22 -> 3 | E23: =D22 -> 4 | F23: =E22 -> 4 | G23: =F22 -> 5
B24: = Unidades a producir | C24: =C21+C22-C23 -> 217 | D24: =D21+D22-D23 -> 238 | E24: =E21+E22-E23 -> 263 | F24: =F21+F22-F23 -> 293 | G24: =G21+G22-G23 -> 324
B26: Unidades de materia prima a comprar
B27: Concepto | C27: 2025 | D27: 2026 | E27: 2027 | F27: 2028 | G27: 2029
B28: Inventario final de materia prima | C28: =ROUNDUP((C29/360)*$E$10,0) -> 198 | D28: =ROUNDUP((D29/360)*$E$10,0) -> 218 | E28: =ROUNDUP((E29/360)*$E$10,0) -> 240 | F28: =ROUNDUP((F29/360)*$E$10,0) -> 264 | G28: =ROUNDUP((G29/360)*$E$10,0) -> 290
B29: + Elementos de materia prima requeridos para la producción | C29: =C49 -> 14227 | D29: =C29*(1+$E$15) -> 15649.7 | E29: =D29*(1+$E$15) -> 17214.67 | F29: =E29*(1+$E$15) -> 18936.137 | G29: =F29*(1+$E$15) -> 20829.751 | I29: El primer dato se toma de la tabla "Detalle de materia prima requerida" (Ver celda B40).
B30: - Inventario inicial de materia prima | C30: 0 | D30: =C28 -> 198 | E30: =D28 -> 218 | F30: =E28 -> 240 | G30: =F28 -> 264
B31: = Unidades de materia prima a comprar | C31: =C28+C29-C30 -> 14425 | D31: =D28+D29-D30 -> 15669.7 | E31: =E28+E29-E30 -> 17236.67 | F31: =F28+F29-F30 -> 18960.137 | G31: =G28+G29-G30 -> 20855.751
B33: Valor de la materia prima a comprar
B34: Concepto | C34: 2025 | D34: 2026 | E34: 2027 | F34: 2028 | G34: 2029
B35: Valor del inventario final de materia prima | C35: =C28*$C$55 -> 432812.04 | D35: =D28*$D$55 -> 495115.11 | E35: =E28*$E$55 -> 565248.85 | F35: =F28*$F$55 -> 644157.59 | G35: =G28*$G$55 -> 732363.26
B36: + Valor de los elementos de materia prima requeridos para la producción | C36: =C29*$C$55 -> 31099075 | D36: =D29*$D$55 -> 35543133 | E36: =E29*$E$55 -> 40544052 | F36: =F29*$F$55 -> 46204001 | G36: =G29*$G$55 -> 52603255
B37: - Valor inventario inicial de materia prima | C37: 0 | D37: =C35 -> 432812.04 | E37: =D35 -> 495115.11 | F37: =E35 -> 565248.85 | G37: =F35 -> 644157.59
B38: = Valor de materia prima a comprar | C38: =C35+C36-C37 -> 31531887 | D38: =D35+D36-D37 -> 35605436 | E38: =E35+E36-E37 -> 40614185 | F38: =F35+F36-F37 -> 46282910 | G38: =G35+G36-G37 -> 52691461
B40: Detalle de materia prima requerida
B41: Concepto | C41: Cantidad | D41: Valor unitario | E41: Valor total
B42: Madera | C42: 87 | D42: 200000 | E42: =C42*D42 -> 17400000
B43: Tornillo | C43: 7118 | D43: 35 | E43: =C43*D43 -> 249130
B44: Pegante | C44: 12 | D44: 7500 | E44: =C44*D44 -> 90000
B45: Lija | C45: 5208 | D45: 1000 | E45: =C45*D45 -> 5208000
B46: Tela | C46: 304 | D46: 25000 | E46: =C46*D46 -> 7600000
B47: Espuma | C47: 109 | D47: 5000 | E47: =C47*D47 -> 545000
B48: Tuerca | C48: 1389 | D48: 5 | E48: =C48*D48 -> 6945
B49: Total | C49: =SUM(C42:C48) -> 14227 | E49: =SUM(E42:E48) -> 31099075
B50: Valor unitario promedio de materia prima | E50: =E49/C49 -> 2185.9194
B52: Nota: aunque en nuestra empresa hipotética se fabrican cinco productos, se realiza una sola tabla de materia prima a comprar y un solo detalle de materia prima requerida, porque la materia prima de los productos es básicamente la misma. El usuario puede realizar un formato por cada artículo comprado o requerido para la producción, y luego proceder con la consolidación.
C54: 2025 | D54: 2026 | E54: 2027 | F54: 2028 | G54: 2029
...

Sheet MOD
B3: Datos para elaborar el presupuesto de mano de obra directa (MOD)
C5: 2025 | D5: 2026 | E5: 2027 | F5: 2028 | G5: 2029
B6: Salario básico | C6: ='Datos base'!C34 -> 1423500 | D6: ='Datos base'!D34 -> 1479016.5 | E6: ='Datos base'!E34 -> 1533740.1 | F6: ='Datos base'!F34 -> 1588954.8 | G6: ='Datos base'!G34 -> 1644568.2
B7: Auxilio de transporte | C7: ='Datos base'!C35 -> 200000 | D7: ='Datos base'!D35 -> 207800 | E7: ='Datos base'!E35 -> 215488.6 | F7: ='Datos base'!F35 -> 223246.19 | G7: ='Datos base'!G35 -> 231059.81
B8: Inflación | C8: ='Datos base'!C33 -> 0.043 | D8: ='Datos base'!D33 -> 0.039 | E8: ='Datos base'!E33 -> 0.037 | F8: ='Datos base'!F33 -> 0.036 | G8: ='Datos base'!G33 -> 0.035
B10: Para el salario básico y el auxilio de transporte del año 2026 y siguientes se considera el incremento conforme a la inflación.
B12: Prestaciones sociales y seguridad social | D12: Factor
B13: Cesantías | D13: ='Datos base'!E44 -> 0.083333333
B14: Intereses de cesantías anual | D14: ='Datos base'!E45 -> 0.12
B15: Prima de servicios | D15: ='Datos base'!E46 -> 0.083333333
B16: Vacaciones | D16: ='Datos base'!E47 -> 0.041666667
B17: Salud | D17: ='Datos base'!E48 -> 0.085
B18: Pensión | D18: ='Datos base'!E49 -> 0.12
B19: Caja de compensación familiar | D19: ='Datos base'!E50 -> 0.04
B20: ARL producción | D20: ='Datos base'!E51 -> 0.02436
B22: Nota: para este caso no se contempla Sena e ICBF conforme a lo estipulado en el parágrafo III del artículo 108 del ET.
B24: Presupuesto de mano de obra directa (teniendo en cuenta 3 trabajadores)
B25: Concepto | C25: 2025 | D25: 2026 | E25: 2027 | F25: 2028 | G25: 2029
B26: Salario básico | C26: =C6*3*12 -> 51246000 | D26: =D6*3*12 -> 53244594 | E26: =E6*3*12 -> 55214644 | F26: =F6*3*12 -> 57202371 | G26: =G6*3*12 -> 59204454
B27: Auxilio de transporte | C27: =C7*3*12 -> 7200000 | D27: =D7*3*12 -> 7480800 | E27: =E7*3*12 -> 7757589.6 | F27: =F7*3*12 -> 8036862.8 | G27: =G7*3*12 -> 8318153
B28: Dotación | C28: 1200000 | D28: =C28*(1+D8) -> 1246800 | E28: =D28*(1+E8) -> 1292931.6 | F28: =E28*(1+F8) -> 1339477.1 | G28: =F28*(1+G8) -> 1386358.8
B29: Cesantías | C29: =(C26+C27)*$D$13 -> 4870500 | D29: =(D26+D27)*$D$13 -> 5060449.5 | E29: =(E26+E27)*$D$13 -> 5247686.1 | F29: =(F26+F27)*$D$13 -> 5436602.8 | G29: =(G26+G27)*$D$13 -> 5626883.9
B30: Intereses a las cesantías | C30: =C29*$D$14 -> 584460 | D30: =D29*$D$14 -> 607253.94 | E30: =E29*$D$14 -> 629722.34 | F30: =F29*$D$14 -> 652392.34 | G30: =G29*$D$14 -> 675226.07
B31: Prima de servicios | C31: =(C26+C27)*$D$15 -> 4870500 | D31: =(D26+D27)*$D$15 -> 5060449.5 | E31: =(E26+E27)*$D$15 -> 5247686.1 | F31: =(F26+F27)*$D$15 -> 5436602.8 | G31: =(G26+G27)*$D$15 -> 5626883.9
B32: Vacaciones | C32: =C26*$D$16 -> 2135250 | D32: =D26*$D$16 -> 2218524.8 | E32: =E26*$D$16 -> 2300610.2 | F32: =F26*$D$16 -> 2383432.1 | G32: =G26*$D$16 -> 2466852.3
B33: Salud | C33: =C26*$D$17 -> 4355910 | D33: =D26*$D$17 -> 4525790.5 | E33: =E26*$D$17 -> 4693244.7 | F33: =F26*$D$17 -> 4862201.5 | G33: =G26*$D$17 -> 5032378.6
B34: Pensión | C34: =C26*$D$18 -> 6149520 | D34: =D26*$D$18 -> 6389351.3 | E34: =E26*$D$18 -> 6625757.3 | F34: =F26*$D$18 -> 6864284.5 | G34: =G26*$D$18 -> 7104534.5
B35: Caja de compensación familiar | C35: =C26*$D$19 -> 2049840 | D35: =D26*$D$19 -> 2129783.8 | E35: =E26*$D$19 -> 2208585.8 | F35: =F26*$D$19 -> 2288094.8 | G35: =G26*$D$19 -> 2368178.2
B36: ARL | C36: =C26*$D$20 -> 1248352.6 | D36: =D26*$D$20 -> 1297038.3 | E36: =E26*$D$20 -> 1345028.7 | F36: =F26*$D$20 -> 1393449.8 | G36: =G26*$D$20 -> 1442220.5
B37: Otros (es necesario especificarlos) | C37: 0 | D37: 0 | E37: 0 | F37: 0 | G37: 0
B38: Total | C38: =SUM(C26:C37) -> 85910333 | D38: =SUM(D26:D37) -> 89260836 | E38: =SUM(E26:E37) -> 92563486 | F38: =SUM(F26:F37) -> 95895772 | G38: =SUM(G26:G37) -> 99252124 | I38: Insumo para el estado de costos

Sheet CIF
B3: Datos para elaborar el presupuesto de costos indirectos de fabricación (CIF)
B5: Costos fijos | C5: Valor | D5: % asumido por producción | E5: Valor asumido por producción
B6: ='Datos base'!B59 -> Arrendamiento | C6: ='Datos base'!C59 -> 18000000 | D6: ='Datos base'!D59 -> 0.75 | E6: =C6*D6 -> 13500000
B7: ='Datos base'!B60 -> Servicios públicos | C7: ='Datos base'!C60 -> 12000000 | D7: ='Datos base'!D60 -> 0.6 | E7: =C7*D7 -> 7200000
B8: ='Datos base'!B61 -> Papelería | C8: ='Datos base'!C61 -> 1000000 | D8: ='Datos base'!D61 -> 0.6 | E8: =C8*D8 -> 600000
B9: ='Datos base'!B62 -> Aseo y mantenimiento | C9: ='Datos base'!C62 -> 6000000 | D9: ='Datos base'!D62 -> 0.6 | E9: =C9*D9 -> 3600000
B11: Concepto | C11: 2025 | D11: 2026 | E11: 2027 | F11: 2028 | G11: 2029
B12: Inflación | C12: ='Datos base'!C33 -> 0.043 | D12: ='Datos base'!D33 -> 0.039 | E12: ='Datos base'!E33 -> 0.037 | F12: ='Datos base'!F33 -> 0.036 | G12: ='Datos base'!G33 -> 0.035
B13: Empaque (unidad) | C13: ='Datos base'!C65 -> 10000 | D13: =C13*(1+D12) -> 10390 | E13: =D13*(1+E12) -> 10774.43 | F13: =E13*(1+F12) -> 11162.309 | G13: =F13*(1+G12) -> 11552.99
B14: Unidades procesadas | C14: ='Ppto Producción'!C65 -> 217 | D14: ='Ppto Producción'!D65 -> 238 | E14: ='Ppto Producción'!E65 -> 263 | F14: ='Ppto Producción'!F65 -> 293 | G14: ='Ppto Producción'!G65 -> 324
B16: Propiedad planta y equipo | C16: Valor de la propiedad planta y equipo | D16: Vida útil (años) | E16: % de depreciación asumida por producción | F16: Depreciación asumida por producción
B17: ='Ppto inversión y plan pagos'!B10 -> Edificio | C17: ='Ppto inversión y plan pagos'!C10 -> 150000000 | D17: ='Datos base'!D68 -> 20 | E17: ='Datos base'!E68 -> 0.6 | F17: =(C17/D17)*$E$17 -> 4500000
B18: ='Ppto inversión y plan pagos'!B11 -> Vehículo | C18: ='Ppto inversión y plan pagos'!C11 -> 50000000 | D18: ='Datos base'!D69 -> 5 | F18: =(C18/D18)*$E$17 -> 6000000
B19: ='Ppto inversión y plan pagos'!B12 -> Maquinaria y equipo | C19: ='Ppto inversión y plan pagos'!C12 -> 24000000 | D19: ='Datos base'!D70 -> 10 | F19: =(C19/D19)*$E$17 -> 1440000
B20: ='Ppto inversión y plan pagos'!B13 -> Equipos de cómputo | C20: ='Ppto inversión y plan pagos'!C13 -> 6000000 | D20: ='Datos base'!D71 -> 3 | F20: =(C20/D20)*$E$17 -> 1200000
B21: ='Ppto inversión y plan pagos'!B14 -> Muebles y enseres | C21: ='Ppto inversión y plan pagos'!C14 -> 12000000 | D21: ='Datos base'!D72 -> 10 | F21: =(C21/D21)*$E$17 -> 720000
B22: Total | C22: =SUM(C17:C21) -> 242000000 | F22: =SUM(F17:F21) -> 13860000
C25: Valores tomados del presupuesto de inversión
B27: Presupuesto costos indirectos de fabricación (CIF)
B28: Concepto | C28: 2025 | D28: 2026 | E28: 2027 | F28: 2028 | G28: 2029
B29: Costos fijos
B30: Arrendamiento | C30: =E6 -> 13500000 | D30: =C30*(1+$D$12) -> 14026500 | E30: =D30*(1+$E$12) -> 14545480 | F30: =E30*(1+$F$12) -> 15069118 | G30: =F30*(1+$G$12) -> 15596537
B31: Servicios públicos | C31: =E7 -> 7200000 | D31: =C31*(1+$D$12) -> 7480800 | E31: =D31*(1+$E$12) -> 7757589.6 | F31: =E31*(1+$F$12) -> 8036862.8 | G31: =F31*(1+$G$12) -> 8318153
B32: Papelería | C32: =E8 -> 600000 | D32: =C32*(1+$D$12) -> 623400 | E32: =D32*(1+$E$12) -> 646465.8 | F32: =E32*(1+$F$12) -> 669738.57 | G32: =F32*(1+$G$12) -> 693179.42
B33: Aseo y mantenimiento | C33: =E9 -> 3600000 | D33: =C33*(1+$D$12) -> 3740400 | E33: =D33*(1+$E$12) -> 3878794.8 | F33: =E33*(1+$F$12) -> 4018431.4 | G33: =F33*(1+$G$12) -> 4159076.5
B34: Depreciación | C34: =F22 -> 13860000 | D34: =+C34 -> 13860000 | E34: =$F$22-$F$20 -> 12660000 | F34: =+E34 -> 12660000 | G34: =+F34-F18 -> 6660000
B35: Total costos fijos | C35: =SUM(C30:C34) -> 38760000 | D35: =SUM(D30:D34) -> 39731100 | E35: =SUM(E30:E34) -> 39488331 | F35: =SUM(F30:F34) -> 40454151 | G35: =SUM(G30:G34) -> 35426946
B36: Costos variables
B37: Empaque | C37: =(C13*C14) -> 2170000 | D37: =(D13*D14) -> 2472820 | E37: =(E13*E14) -> 2833675.1 | F37: =(F13*F14) -> 3270556.7 | G37: =(G13*G14) -> 3743168.9
B38: Total costos variables | C38: =C37 -> 2170000 | D38: =D37 -> 2472820 | E38: =E37 -> 2833675.1 | F38: =F37 -> 3270556.7 | G38: =G37 -> 3743168.9
B39: Total | C39: =C35+C38 -> 40930000 | D39: =D35+D38 -> 42203920 | E39: =E35+E38 -> 42322006 | F39: =F35+F38 -> 43724707 | G39: =G35+G38 -> 39170115 | I39: Insumo para el estado de costos

Sheet Admón y ventas
B3: Datos para elaborar el presupuesto de gastos de administración y ventas
C5: 2025 | D5: 2026 | E5: 2027 | F5: 2028 | G5: 2029
B6: Salario básico | C6: ='Datos base'!C34 -> 1423500 | D6: ='Datos base'!D34 -> 1479016.5 | E6: ='Datos base'!E34 -> 1533740.1 | F6: ='Datos base'!F34 -> 1588954.8 | G6: ='Datos base'!G34 -> 1644568.2
B7: Auxilio de transporte | C7: ='Datos base'!C35 -> 200000 | D7: ='Datos base'!D35 -> 207800 | E7: ='Datos base'!E35 -> 215488.6 | F7: ='Datos base'!F35 -> 223246.19 | G7: ='Datos base'!G35 -> 231059.81
B8: Inflación | C8: ='Datos base'!C33 -> 0.043 | D8: ='Datos base'!D33 -> 0.039 | E8: ='Datos base'!E33 -> 0.037 | F8: ='Datos base'!F33 -> 0.036 | G8: ='Datos base'!G33 -> 0.035
B10: Para el salario básico y el auxilio de transporte del año 2026 y siguientes se considera el incremento conforme a la inflación.
B12: Prestaciones sociales y seguridad social | D12: Factor
B13: Cesantías | D13: ='Datos base'!E44 -> 0.083333333
B14: Intereses de cesantías anual | D14: ='Datos base'!E45 -> 0.12
B15: Prima de servicios | D15: ='Datos base'!E46 -> 0.083333333
B16: Vacaciones | D16: ='Datos base'!E47 -> 0.041666667
B17: Salud | D17: ='Datos base'!E48 -> 0.085
B18: Pensión | D18: ='Datos base'!E49 -> 0.12
B19: Caja de compensación familiar | D19: ='Datos base'!E50 -> 0.04
B20: ARL administración y ventas | D20: ='Datos base'!E52 -> 0.00522
B22: Nota: para este caso no se contempla Sena e ICBF conforme a lo estipulado en el parágrafo III del artículo 108 del ET.
B24: Costos fijos | C24: Valor | D24: % asumido por administración y ventas | E24: Valor asumido por administración y ventas
B25: ='Datos base'!B59 -> Arrendamiento | C25: ='Datos base'!C59 -> 18000000 | D25: ='Datos base'!E59 -> 0.25 | E25: =C25*D25 -> 4500000
B26: ='Datos base'!B60 -> Servicios públicos | C26: ='Datos base'!C60 -> 12000000 | D26: ='Datos base'!E60 -> 0.4 | E26: =C26*D26 -> 4800000
B27: ='Datos base'!B61 -> Papelería | C27: ='Datos base'!C61 -> 1000000 | D27: ='Datos base'!E61 -> 0.4 | E27: =C27*D27 -> 400000
B28: ='Datos base'!B62 -> Aseo y mantenimiento | C28: ='Datos base'!C62 -> 6000000 | D28: ='Datos base'!E62 -> 0.4 | E28: =C28*D28 -> 2400000
B30: Propiedad planta y equipo | C30: Valor de la propiedad planta y equipo | D30: Vida útil (años) | E30: % de depreciación asumida por administración y ventas | F30: Depreciación asumida por administración y ventas
B31: ='Ppto inversión y plan pagos'!B10 -> Edificio | C31: ='Ppto inversión y plan pagos'!C10 -> 150000000 | D31: ='Datos base'!D68 -> 20 | E31: ='Datos base'!F68 -> 0.4 | F31: =(C31/D31)*$E$31 -> 3000000
B32: ='Ppto inversión y plan pagos'!B11 -> Vehículo | C32: ='Ppto inversión y plan pagos'!C11 -> 50000000 | D32: ='Datos base'!D69 -> 5 | F32: =(C32/D32)*$E$31 -> 4000000
B33: ='Ppto inversión y plan pagos'!B12 -> Maquinaria y equipo | C33: ='Ppto inversión y plan pagos'!C12 -> 24000000 | D33: ='Datos base'!D70 -> 10 | F33: =(C33/D33)*$E$31 -> 960000
B34: ='Ppto inversión y plan pagos'!B13 -> Equipos de cómputo | C34: ='Ppto inversión y plan pagos'!C13 -> 6000000 | D34: ='Datos base'!D71 -> 3 | F34: =(C34/D34)*$E$31 -> 800000
B35: ='Ppto inversión y plan pagos'!B14 -> Muebles y enseres | C35: ='Ppto inversión y plan pagos'!C14 -> 12000000 | D35: ='Datos base'!D72 -> 10 | F35: =(C35/D35)*$E$31 -> 480000
B36: Total | C36: =SUM(C31:C35) -> 242000000 | F36: =SUM(F31:F35) -> 9240000
C39: Valores tomados del presupuesto de inversión
B41: Presupuesto de gastos de administración y ventas (teniendo en cuenta 4 trabajadores)
B42: Concepto | C42: 2025 | D42: 2026 | E42: 2027 | F42: 2028 | G42: 2029
B43: Nómina de administración y ventas
B44: Salario básico | C44: =C6*4*12 -> 68328000 | D44: =D6*4*12 -> 70992792 | E44: =E6*4*12 -> 73619525 | F44: =F6*4*12 -> 76269828 | G44: =G6*4*12 -> 78939272
B45: Auxilio de transporte | C45: =C7*4*12 -> 9600000 | D45: =D7*4*12 -> 9974400 | E45: =E7*4*12 -> 10343453 | F45: =F7*4*12 -> 10715817 | G45: =G7*4*12 -> 11090871
B46: Dotación | C46: 1500000 | D46: =C46*(1+D8) -> 1558500 | E46: =D46*(1+E8) -> 1616164.5 | F46: =E46*(1+F8) -> 1674346.4 | G46: =F46*(1+G8) -> 1732948.5
B47: Cesantías | C47: =(C44+C45)*$D$13 -> 6494000 | D47: =(D44+D45)*$D$13 -> 6747266 | E47: =(E44+E45)*$D$13 -> 6996914.8 | F47: =(F44+F45)*$D$13 -> 7248803.8 | G47: =(G44+G45)*$D$13 -> 7502511.9
B48: Intereses a las cesantías | C48: =C47*$D$14 -> 779280 | D48: =D47*$D$14 -> 809671.92 | E48: =E47*$D$14 -> 839629.78 | F48: =F47*$D$14 -> 869856.45 | G48: =G47*$D$14 -> 900301.43
B49: Prima de servicios | C49: =(C44+C45)*$D$15 -> 6494000 | D49: =(D44+D45)*$D$15 -> 6747266 | E49: =(E44+E45)*$D$15 -> 6996914.8 | F49: =(F44+F45)*$D$15 -> 7248803.8 | G49: =(G44+G45)*$D$15 -> 7502511.9
B50: Vacaciones | C50: =C44*$D$16 -> 2847000 | D50: =D44*$D$16 -> 2958033 | E50: =E44*$D$16 -> 3067480.2 | F50: =F44*$D$16 -> 3177909.5 | G50: =G44*$D$16 -> 3289136.3
B51: Salud | C51: =C44*$D$17 -> 5807880 | D51: =D44*$D$17 -> 6034387.3 | E51: =E44*$D$17 -> 6257659.7 | F51: =F44*$D$17 -> 6482935.4 | G51: =G44*$D$17 -> 6709838.1
...

Sheet Ppto Cartera
B3: Datos para elaborar el presupuesto de cartera
B5: Política de cobro de cartera en días | D5: ='Datos base'!F17 -> 15
B6: Porcentaje de ventas a crédito | D6: ='Datos base'!F18 -> 0.6
C8: 2025 | D8: 2026 | E8: 2027 | F8: 2028 | G8: 2029
B9: Total ventas | C9: ='Ppto Ventas'!D37 -> 308860000 | D9: ='Ppto Ventas'!E37 -> 3.5490162e+08 | E9: ='Ppto Ventas'!F37 -> 4.0840477e+08 | F9: ='Ppto Ventas'!G37 -> 4.6962068e+08 | G9: ='Ppto Ventas'!H37 -> 5.3925893e+08
B11: Presupuesto de cartera
B12: Concepto | C12: 2025 | D12: 2026 | E12: 2027 | F12: 2028 | G12: 2029
B13: Saldo inicial de cartera | C13: 0 | D13: =C15 -> 7721500 | E13: =D15 -> 8872540.5 | F13: =E15 -> 10210119 | G13: =F15 -> 11740517
B14: + Ventas a crédito | C14: =C9*$D$6 -> 185316000 | D14: =D9*$D$6 -> 2.1294097e+08 | E14: =E9*$D$6 -> 2.4504286e+08 | F14: =F9*$D$6 -> 2.8177241e+08 | G14: =G9*$D$6 -> 3.2355536e+08
B15: - Saldo final de cartera | C15: =(C14/360)*$D$5 -> 7721500 | D15: =(D14/360)*$D$5 -> 8872540.5 | E15: =(E14/360)*$D$5 -> 10210119 | F15: =(F14/360)*$D$5 -> 11740517 | G15: =(G14/360)*$D$5 -> 13481473 | I15: Insumo para el estado de situación financiera
B16: Total recaudo de cartera | C16: =C13+C14-C15 -> 177594500 | D16: =D13+D14-D15 -> 2.1178993e+08 | E16: =E13+E14-E15 -> 2.4370528e+08 | F16: =F13+F14-F15 -> 2.8024201e+08 | G16: =G13+G14-G15 -> 3.218144e+08 | I16: Insumo para el flujo de caja

Sheet Ppto inversión y plan pagos
B3: Datos para elaborar el presupuesto de inversión inicial
B5: Aportes de socios | C5: 155000000
B7: Presupuesto de inversión inicial
B8: Concepto | C8: Valor
B9: Inversión fija
B10: Edificio | C10: 150000000
B11: Vehículo | C11: 50000000
B12: Maquinaria y equipo | C12: 24000000
B13: Equipos de cómputo | C13: 6000000
B14: Muebles y enseres | C14: 12000000
B15: Total inversión fija | C15: =SUM(C10:C14) -> 242000000 | E15: Insumo para el flujo de caja
B16: Efectivo | C16: 3000000
B17: Total | C17: =C15+C16 -> 245000000
B19: Aportes de socios | C19: =C5 -> 155000000 | E19: Insumo para el flujo de caja
B20: Financiación a largo plazo | C20: =C17-C19 -> 90000000
B22: Datos para elaborar el plan de pagos o amortización de préstamos a largo plazo
B24: Costo de la obligación financiera | C24: ='Datos base'!F21 -> 0.25
B26: Plan de pagos o amortización de préstamos a largo plazo
B27: Año | C27: Interés anual | D27: Abono a capital | E27: Saldo
B28: 0 | E28: =C20 -> 90000000 | G28: Insumo para el flujo de caja
B29: 1 | C29: =E28*$C$24 -> 22500000 | D29: =$E$28/$B$33 -> 18000000 | E29: =E28-D29 -> 72000000
B30: 2 | C30: =E29*$C$24 -> 18000000 | D30: =$E$28/$B$33 -> 18000000 | E30: =E29-D30 -> 54000000
B31: 3 | C31: =E30*$C$24 -> 13500000 | D31: =$E$28/$B$33 -> 18000000 | E31: =E30-D31 -> 36000000
B32: 4 | C32: =E31*$C$24 -> 9000000 | D32: =$E$28/$B$33 -> 18000000 | E32: =E31-D32 -> 18000000
B33: 5 | C33: =E32*$C$24 -> 4500000 | D33: =$E$28/$B$33 -> 18000000 | E33: =E32-D33 -> 0
C36: Insumo para el flujo de caja | E36: Insumo para el estado de situación financiera
C40: Beneficio para deducción en el impuesto de renta

Sheet Estado costos
B3: Datos para elaborar el estado de costos
B5: Estado de costos proyectado | C5: 2025 | D5: 2026 | E5: 2027 | F5: 2028 | G5: 2029
B6: Inventario inicial de materia prima | C6: ='Ppto Producción'!C69 -> 0 | D6: ='Ppto Producción'!D69 -> 432812.04 | E6: ='Ppto Producción'!E69 -> 495115.11 | F6: ='Ppto Producción'!F69 -> 565248.85 | G6: ='Ppto Producción'!G69 -> 644157.59
B7: + Compra de materiales | C7: ='Ppto Producción'!C70 -> 31531887 | D7: ='Ppto Producción'!D70 -> 35605436 | E7: ='Ppto Producción'!E70 -> 40614185 | F7: ='Ppto Producción'!F70 -> 46282910 | G7: ='Ppto Producción'!G70 -> 52691461
B8: = Materiales disponibles | C8: =C6+C7 -> 31531887 | D8: =D6+D7 -> 36038248 | E8: =E6+E7 -> 41109300 | F8: =F6+F7 -> 46848159 | G8: =G6+G7 -> 53335619 | I8: Valores tomados del presupuesto de producción
B9: - Inventario final | C9: ='Ppto Producción'!C68 -> 432812.04 | D9: ='Ppto Producción'!D68 -> 495115.11 | E9: ='Ppto Producción'!E68 -> 565248.85 | F9: ='Ppto Producción'!F68 -> 644157.59 | G9: ='Ppto Producción'!G68 -> 732363.26
B10: = Material usado | C10: =C8-C9 -> 31099075 | D10: =D8-D9 -> 35543133 | E10: =E8-E9 -> 40544052 | F10: =F8-F9 -> 46204001 | G10: =G8-G9 -> 52603255
B11: + Mano de obra directa | C11: =MOD!C38 -> 85910333 | D11: =MOD!D38 -> 89260836 | E11: =MOD!E38 -> 92563486 | F11: =MOD!F38 -> 95895772 | G11: =MOD!G38 -> 99252124 | I11: Valores tomados del presupuesto de mano de obra directa
B12: + CIF | C12: =CIF!C39 -> 40930000 | D12: =CIF!D39 -> 42203920 | E12: =CIF!E39 -> 42322006 | F12: =CIF!F39 -> 43724707 | G12: =CIF!G39 -> 39170115 | I12: Valores tomados del presupuesto de costos indirectos de fabricación
B13: = Costo de fabricación o producción | C13: =C10+C11+C12 -> 1.5793941e+08 | D13: =D10+D11+D12 -> 1.6700789e+08 | E13: =E10+E11+E12 -> 1.7542954e+08 | F13: =F10+F11+F12 -> 1.8582448e+08 | G13: =G10+G11+G12 -> 1.9102549e+08
B14: + Inventario inicial de productos terminados | C14: 0 | D14: =C16 -> 2183494.1 | E14: =D16 -> 2806855.3 | F14: =E16 -> 2668129.9 | G14: =F16 -> 3171066.2 | I14: Valores tomados del presupuesto de producción
B15: = Mercancía disponible | C15: =C13+C14 -> 1.5793941e+08 | D15: =D13+D14 -> 1.6919138e+08 | E15: =E13+E14 -> 1.782364e+08 | F15: =F13+F14 -> 1.8849261e+08 | G15: =G13+G14 -> 1.9419656e+08
B16: - Inventario final de productos terminados | C16: =(C13/'Ppto Producción'!C65)*'Ppto Producción'!C60 -> 2183494.1 | D16: =(D13/'Ppto Producción'!D65)*'Ppto Producción'!D60 -> 2806855.3 | E16: =(E13/'Ppto Producción'!E65)*'Ppto Producción'!E60 -> 2668129.9 | F16: =(F13/'Ppto Producción'!F65)*'Ppto Producción'!F60 -> 3171066.2 | G16: =(G13/'Ppto Producción'!G65)*'Ppto Producción'!G60 -> 2947924.3
B17: = Costo de ventas | C17: =C15-C16 -> 1.5575591e+08 | D17: =D15-D16 -> 1.6638453e+08 | E17: =E15-E16 -> 1.7556827e+08 | F17: =F15-F16 -> 1.8532154e+08 | G17: =G15-G16 -> 1.9124864e+08 | I17: Insumo para el estado de resultados

Sheet ER
B3: Datos para elaborar el estado de resultados proyectado
B5: Tarifa impuesto de renta | C5: ='Datos base'!F22 -> 0.35
B6: Reserva legal | C6: ='Datos base'!F23 -> 0.1
B8: Estado de resultados proyectado | C8: 2025 | D8: 2026 | E8: 2027 | F8: 2028 | G8: 2029
B9: Ventas netas | C9: ='Ppto Ventas'!D37 -> 308860000 | D9: ='Ppto Ventas'!E37 -> 3.5490162e+08 | E9: ='Ppto Ventas'!F37 -> 4.0840477e+08 | F9: ='Ppto Ventas'!G37 -> 4.6962068e+08 | G9: ='Ppto Ventas'!H37 -> 5.3925893e+08 | I9: Valores tomados del presupuesto de ventas
B10: - Costo de ventas | C10: ='Estado costos'!C17 -> 1.5575591e+08 | D10: ='Estado costos'!D17 -> 1.6638453e+08 | E10: ='Estado costos'!E17 -> 1.7556827e+08 | F10: ='Estado costos'!F17 -> 1.8532154e+08 | G10: ='Estado costos'!G17 -> 1.9124864e+08 | I10: Valores tomados del estado de costos
B11: = Utilidad bruta | C11: =C9-C10 -> 1.5310409e+08 | D11: =D9-D10 -> 1.8851709e+08 | E11: =E9-E10 -> 2.328365e+08 | F11: =F9-F10 -> 2.8429914e+08 | G11: =G9-G10 -> 3.4801029e+08
B12: - Gasos de administración | C12: ='Admón y ventas'!C64 -> 1.3447931e+08 | D12: ='Admón y ventas'!D64 -> 1.3936365e+08 | E12: ='Admón y ventas'!E64 -> 1.4337822e+08 | F12: ='Admón y ventas'!F64 -> 1.48236e+08 | G12: ='Admón y ventas'!G64 -> 1.4912886e+08 | I12: Valores tomados del presupuesto de administración y ventas
B13: = Utilidad operacional | C13: =C11-C12 -> 18624774 | D13: =D11-D12 -> 49153447 | E13: =E11-E12 -> 89458280 | F13: =F11-F12 -> 1.3606314e+08 | G13: =G11-G12 -> 1.9888144e+08
B14: + Ingresos financieros | C14: 10000000 | D14: 0 | E14: 0 | F14: 0 | G14: 0 | I14: Insumo para el flujo de caja
B15: - Gastos financieros | C15: ='Ppto inversión y plan pagos'!C29 -> 22500000 | D15: ='Ppto inversión y plan pagos'!C30 -> 18000000 | E15: ='Ppto inversión y plan pagos'!C31 -> 13500000 | F15: ='Ppto inversión y plan pagos'!C32 -> 9000000 | G15: ='Ppto inversión y plan pagos'!C33 -> 4500000 | I15: Valores tomados de la amortización de préstamos a largo plazo
B16: = Utilidad antes de impuestos | C16: =C13+C14-C15 -> 6124774.4 | D16: =D13+D14-D15 -> 31153447 | E16: =E13+E14-E15 -> 75958280 | F16: =F13+F14-F15 -> 1.2706314e+08 | G16: =G13+G14-G15 -> 1.9438144e+08
B17: - Impuesto de renta | C17: =C16*$C$5 -> 2143671 | D17: =D16*$C$5 -> 10903707 | E17: =E16*$C$5 -> 26585398 | F17: =F16*$C$5 -> 44472100 | G17: =G16*$C$5 -> 68033503 | I17: Insumo para el flujo de caja
B18: = Utilidad neta | C18: =C16-C17 -> 3981103.4 | D18: =D16-D17 -> 20249741 | E18: =E16-E17 -> 49372882 | F18: =F16-F17 -> 82591044 | G18: =G16-G17 -> 1.2634793e+08
B19: - Reserva legal | C19: =C18*$C$6 -> 398110.34 | D19: =D18*$C$6 -> 2024974.1 | E19: =E18*$C$6 -> 4937288.2 | F19: =F18*$C$6 -> 8259104.4 | G19: =G18*$C$6 -> 12634793 | I19: Insumo para el estado de situación financiera
B20: = Utilidad del ejercicio | C20: =C18-C19 -> 3582993 | D20: =D18-D19 -> 18224767 | E20: =E18-E19 -> 44435594 | F20: =F18-F19 -> 74331939 | G20: =G18-G19 -> 1.1371314e+08 | I20: Insumo para el estado de situación financiera

Sheet FC
B3: Datos para elaborar el flujo de caja proyectado
B5: Aportes de socios | C5: ='Datos base'!F20 -> 155000000
B6: Porcentaje de ventas a contado | C6: ='Datos base'!F19 -> 0.4
B7: Política de pago a proveedores en días | C7: ='Datos base'!F24 -> 30
B9: Sobre la nómina de producción, administración y ventas, queda causado para el siguiente año el valor de las cesantías, intereses sobre cesantías, vacaciones, y el valor correspondiente a un mes de salud, pensión, caja de compensación y ARL.
B11: Valores de nómina que quedan causados (nómina producción) | C11: 2025 | D11: 2026 | E11: 2027 | F11: 2028 | G11: 2029
B12: Cesantías | C12: =MOD!C29 -> 4870500 | D12: =MOD!D29 -> 5060449.5 | E12: =MOD!E29 -> 5247686.1 | F12: =MOD!F29 -> 5436602.8 | G12: =MOD!G29 -> 5626883.9 | I12: Insumo para el flujo de caja y el estado de situación financiera
B13: Intereses a las cesantías | C13: =MOD!C30 -> 584460 | D13: =MOD!D30 -> 607253.94 | E13: =MOD!E30 -> 629722.34 | F13: =MOD!F30 -> 652392.34 | G13: =MOD!G30 -> 675226.07
B14: Vacaciones | C14: =MOD!C32 -> 2135250 | D14: =MOD!D32 -> 2218524.8 | E14: =MOD!E32 -> 2300610.2 | F14: =MOD!F32 -> 2383432.1 | G14: =MOD!G32 -> 2466852.3
B15: Salud | C15: =MOD!C33/12 -> 362992.5 | D15: =MOD!D33/12 -> 377149.21 | E15: =MOD!E33/12 -> 391103.73 | F15: =MOD!F33/12 -> 405183.46 | G15: =MOD!G33/12 -> 419364.88
B16: Pensión | C16: =MOD!C34/12 -> 512460 | D16: =MOD!D34/12 -> 532445.94 | E16: =MOD!E34/12 -> 552146.44 | F16: =MOD!F34/12 -> 572023.71 | G16: =MOD!G34/12 -> 592044.54
B17: Caja de compensación familiar | C17: =MOD!C35/12 -> 170820 | D17: =MOD!D35/12 -> 177481.98 | E17: =MOD!E35/12 -> 184048.81 | F17: =MOD!F35/12 -> 190674.57 | G17: =MOD!G35/12 -> 197348.18
B18: ARL | C18: =MOD!C36/12 -> 104029.38 | D18: =MOD!D36/12 -> 108086.53 | E18: =MOD!E36/12 -> 112085.73 | F18: =MOD!F36/12 -> 116120.81 | G18: =MOD!G36/12 -> 120185.04
B19: Total | C19: =SUM(C12:C18) -> 8740511.9 | D19: =SUM(D12:D18) -> 9081391.8 | E19: =SUM(E12:E18) -> 9417403.3 | F19: =SUM(F12:F18) -> 9756429.9 | G19: =SUM(G12:G18) -> 10097905
B21: Valores de nómina que quedan causados (nómina administración y ventas) | C21: 2025 | D21: 2026 | E21: 2027 | F21: 2028 | G21: 2029
B22: Cesantías | C22: ='Admón y ventas'!C47 -> 6494000 | D22: ='Admón y ventas'!D47 -> 6747266 | E22: ='Admón y ventas'!E47 -> 6996914.8 | F22: ='Admón y ventas'!F47 -> 7248803.8 | G22: ='Admón y ventas'!G47 -> 7502511.9 | I22: Insumo para el flujo de caja y el estado de situación financiera
B23: Intereses a las cesantías | C23: ='Admón y ventas'!C48 -> 779280 | D23: ='Admón y ventas'!D48 -> 809671.92 | E23: ='Admón y ventas'!E48 -> 839629.78 | F23: ='Admón y ventas'!F48 -> 869856.45 | G23: ='Admón y ventas'!G48 -> 900301.43
B24: Vacaciones | C24: ='Admón y ventas'!C50 -> 2847000 | D24: ='Admón y ventas'!D50 -> 2958033 | E24: ='Admón y ventas'!E50 -> 3067480.2 | F24: ='Admón y ventas'!F50 -> 3177909.5 | G24: ='Admón y ventas'!G50 -> 3289136.3
B25: Salud | C25: ='Admón y ventas'!C51/12 -> 483990 | D25: ='Admón y ventas'!D51/12 -> 502865.61 | E25: ='Admón y ventas'!E51/12 -> 521471.64 | F25: ='Admón y ventas'!F51/12 -> 540244.62 | G25: ='Admón y ventas'!G51/12 -> 559153.18
B26: Pensión | C26: ='Admón y ventas'!C52/12 -> 683280 | D26: ='Admón y ventas'!D52/12 -> 709927.92 | E26: ='Admón y ventas'!E52/12 -> 736195.25 | F26: ='Admón y ventas'!F52/12 -> 762698.28 | G26: ='Admón y ventas'!G52/12 -> 789392.72
B27: Caja de compensación familiar | C27: ='Admón y ventas'!C53/12 -> 227760 | D27: ='Admón y ventas'!D53/12 -> 236642.64 | E27: ='Admón y ventas'!E53/12 -> 245398.42 | F27: ='Admón y ventas'!F53/12 -> 254232.76 | G27: ='Admón y ventas'!G53/12 -> 263130.91
B28: ARL | C28: ='Admón y ventas'!C54/12 -> 29722.68 | D28: ='Admón y ventas'!D54/12 -> 30881.865 | E28: ='Admón y ventas'!E54/12 -> 32024.494 | F28: ='Admón y ventas'!F54/12 -> 33177.375 | G28: ='Admón y ventas'!G54/12 -> 34338.583
B29: Total | C29: =SUM(C22:C28) -> 11545033 | D29: =SUM(D22:D28) -> 11995289 | E29: =SUM(E22:E28) -> 12439115 | F29: =SUM(F22:F28) -> 12886923 | G29: =SUM(G22:G28) -> 13337965
B32: Flujo de caja proyectado | C32: Año 0 | D32: 2025 | E32: 2026 | F32: 2027 | G32: 2028 | H32: 2029
B33: Saldo inicial | C33: 0 | D33: 0 | E33: =D53 -> 23800170 | F33: =E53 -> 59831498 | G33: =F53 -> 1.3088144e+08 | H33: =G53 -> 2.3699068e+08
B34: Ingresos en efectivo | C34: =SUM(C35:C39) -> 245000000 | D34: =SUM(D35:D39) -> 311138500 | E34: =SUM(E35:E39) -> 3.5375058e+08 | F34: =SUM(F35:F39) -> 4.0706719e+08 | G34: =SUM(G35:G39) -> 4.6809029e+08 | H34: =SUM(H35:H39) -> 5.3751797e+08
B35: Aporte de socios | C35: =C5 -> 155000000 | D35: 0 | E35: 0 | F35: 0 | G35: 0 | H35: 0 | J35: Valores tomados del presupuesto de inversión y la amortización de préstamos a largo plazo
B36: Créditos financiación | C36: ='Ppto inversión y plan pagos'!E28 -> 90000000 | D36: 0 | E36: 0 | F36: 0 | G36: 0 | H36: 0
B37: Ventas de contado | C37: 0 | D37: ='Ppto Ventas'!D37*FC!$C$6 -> 123544000 | E37: ='Ppto Ventas'!E37*FC!$C$6 -> 1.4196065e+08 | F37: ='Ppto Ventas'!F37*FC!$C$6 -> 1.6336191e+08 | G37: ='Ppto Ventas'!G37*FC!$C$6 -> 1.8784827e+08 | H37: ='Ppto Ventas'!H37*FC!$C$6 -> 2.1570357e+08
B38: Recaudos de cartera | C38: 0 | D38: ='Ppto Cartera'!C16 -> 177594500 | E38: ='Ppto Cartera'!D16 -> 2.1178993e+08 | F38: ='Ppto Cartera'!E16 -> 2.4370528e+08 | G38: ='Ppto Cartera'!F16 -> 2.8024201e+08 | H38: ='Ppto Cartera'!G16 -> 3.218144e+08 | J38: Valores tomados del presupuesto de cartera
B39: Otros ingresos | C39: 0 | D39: =ER!C14 -> 10000000 | E39: =ER!D14 -> 0 | F39: =ER!E14 -> 0 | G39: =ER!F14 -> 0 | H39: =ER!G14 -> 0 | J39: Valores tomados del estado de resultados
B40: Egresos en efectivo | C40: =SUM(C41:C50) -> 242000000 | D40: =SUM(D41:D50) -> 2.8733833e+08 | E40: =SUM(E41:E50) -> 3.1771925e+08 | F40: =SUM(F41:F50) -> 3.3601725e+08 | G40: =SUM(G41:G50) -> 3.6198104e+08 | H40: =SUM(H41:H50) -> 3.9093118e+08
B41: Inversión fija | C41: ='Ppto inversión y plan pagos'!C15 -> 242000000 | D41: 0 | E41: 0 | F41: 0 | G41: 0 | H41: 0 | J41: Valor tomado del presupuesto de inversión
B42: Pagos a proveedores | C42: 0 | D42: =('Ppto Producción'!C70/12)*11 -> 28904230 | E42: =('Ppto Producción'!D70/12)*11 -> 32638316 | F42: =('Ppto Producción'!E70/12)*11 -> 37229670 | G42: =('Ppto Producción'!F70/12)*11 -> 42426001 | H42: =('Ppto Producción'!G70/12)*11 -> 48300506 | J42: Valores a partir del presupuesto de producción
B43: Pago mano de obra | C43: 0 | D43: =MOD!C38-FC!C19 -> 77169821 | E43: =MOD!D38-FC!D19 -> 80179444 | F43: =MOD!E38-FC!E19 -> 83146083 | G43: =MOD!F38-FC!F19 -> 86139342 | H43: =MOD!G38-FC!G19 -> 89154219 | J43: Valores a partir del presupuesto de mano de obra directa
B44: Pagos CIF | C44: 0 | D44: =CIF!C39-CIF!C34 -> 27070000 | E44: =CIF!D39-CIF!D34 -> 28343920 | F44: =CIF!E39-CIF!E34 -> 29662006 | G44: =CIF!F39-CIF!F34 -> 31064707 | H44: =CIF!G39-CIF!G34 -> 32510115 | J44: Valores a partir del presupuesto de costos indirectos de fabricación
B45: Pagos de administración | C45: 0 | D45: ='Admón y ventas'!C64-'Admón y ventas'!C62-FC!C29 -> 1.1369428e+08 | E45: ='Admón y ventas'!D64-'Admón y ventas'!D62-FC!D29 -> 1.1812836e+08 | F45: ='Admón y ventas'!E64-'Admón y ventas'!E62-FC!E29 -> 1.2249911e+08 | G45: ='Admón y ventas'!F64-'Admón y ventas'!F62-FC!F29 -> 1.2690907e+08 | H45: ='Admón y ventas'!G64-'Admón y ventas'!G62-FC!G29 -> 1.3135089e+08 | J45: Valores a partir del presupuesto de gastos de administración y ventas
B46: Pago acreedores | C46: 0 | D46: 0 | E46: =SUM(C15:C18,C25:C28) -> 2575054.6 | F46: =SUM(D15:D18,D25:D28) -> 2675481.7 | G46: =SUM(E15:E18,E25:E28) -> 2774474.5 | H46: =SUM(F15:F18,F25:F28) -> 2874355.6
B47: Pago por pasivos laborales | C47: 0 | D47: 0 | E47: =SUM(C12:C14,C22:C24) -> 17710490 | F47: =SUM(D12:D14,D22:D24) -> 18401199 | G47: =SUM(E12:E14,E22:E24) -> 19082043 | H47: =SUM(F12:F14,F22:F24) -> 19768997 | I47: =+C19+C29-E46-E47 -> 0 | J47: =+D19+D29-F46-F47 -> 0 | K47: =+E19+E29-G46-G47 -> 0 | L47: =+F19+F29-H46-H47 -> 0
B48: Pago impuesto de renta | C48: 0 | D48: 0 | E48: =ER!C17 -> 2143671 | F48: =ER!D17 -> 10903707 | G48: =ER!E17 -> 26585398 | H48: =ER!F17 -> 44472100 | J48: Valores tomados del estado de resultados
...

Sheet ESF
B3: Datos para elaborar el estado de situación financiera proyectado
B5: Aportes de socios | C5: ='Datos base'!F20 -> 155000000
B7: Estado de situación financiera proyectado | C7: Año 0 | D7: 2025 | E7: 2026 | F7: 2027 | G7: 2028 | H7: 2029
B8: Activo
B9: Activo corriente
B10: Efectivo | C10: =FC!C53 -> 3000000 | D10: =FC!D53 -> 23800170 | E10: =FC!E53 -> 59831498 | F10: =FC!F53 -> 1.3088144e+08 | G10: =FC!G53 -> 2.3699068e+08 | H10: =FC!H53 -> 3.8357747e+08 | J10: Valores tomados del flujo de caja
B11: Clientes | C11: 0 | D11: ='Ppto Cartera'!C15 -> 7721500 | E11: ='Ppto Cartera'!D15 -> 8872540.5 | F11: ='Ppto Cartera'!E15 -> 10210119 | G11: ='Ppto Cartera'!F15 -> 11740517 | H11: ='Ppto Cartera'!G15 -> 13481473 | J11: Valores tomados del presupuesto de caja
B12: Inventario materia prima | C12: 0 | D12: ='Estado costos'!C9 -> 432812.04 | E12: ='Estado costos'!D9 -> 495115.11 | F12: ='Estado costos'!E9 -> 565248.85 | G12: ='Estado costos'!F9 -> 644157.59 | H12: ='Estado costos'!G9 -> 732363.26 | J12: Valores tomados del estado de costos
B13: Inventario producto terminado | C13: 0 | D13: ='Estado costos'!C16 -> 2183494.1 | E13: ='Estado costos'!D16 -> 2806855.3 | F13: ='Estado costos'!E16 -> 2668129.9 | G13: ='Estado costos'!F16 -> 3171066.2 | H13: ='Estado costos'!G16 -> 2947924.3 | J13: Valores tomados del estado de costos
B14: Inversión temporal | C14: =FC!C52 -> 0 | D14: =FC!D52 -> 0 | E14: =FC!E52 -> 0 | F14: =FC!F52 -> 0 | G14: =FC!G52 -> 0 | H14: =FC!H52 -> 0 | J14: Valores tomados del flujo de caja
B15: Total activo corriente | C15: =SUM(C10:C14) -> 3000000 | D15: =SUM(D10:D14) -> 34137976 | E15: =SUM(E10:E14) -> 72006009 | F15: =SUM(F10:F14) -> 1.4432493e+08 | G15: =SUM(G10:G14) -> 2.5254642e+08 | H15: =SUM(H10:H14) -> 4.0073923e+08
B16: Activo no corriente
B17: Edificios | C17: ='Ppto inversión y plan pagos'!C10 -> 150000000 | D17: =$C$17 -> 150000000 | E17: =$C$17 -> 150000000 | F17: =$C$17 -> 150000000 | G17: =$C$17 -> 150000000 | H17: =$C$17 -> 150000000
B18: Vehículos | C18: ='Ppto inversión y plan pagos'!C11 -> 50000000 | D18: =$C$18 -> 50000000 | E18: =$C$18 -> 50000000 | F18: =$C$18 -> 50000000 | G18: =$C$18 -> 50000000 | H18: =$C$18 -> 50000000
B19: Maquinaria y equipo | C19: ='Ppto inversión y plan pagos'!C12 -> 24000000 | D19: =$C$19 -> 24000000 | E19: =$C$19 -> 24000000 | F19: =$C$19 -> 24000000 | G19: =$C$19 -> 24000000 | H19: =$C$19 -> 24000000 | J19: Valores tomados del presupuesto de inversión
B20: Equipo de cómputo | C20: ='Ppto inversión y plan pagos'!C13 -> 6000000 | D20: =$C$20 -> 6000000 | E20: =$C$20 -> 6000000 | F20: =$C$20 -> 6000000 | G20: =$C$20 -> 6000000 | H20: =$C$20 -> 6000000
B21: Muebles y enseres | C21: ='Ppto inversión y plan pagos'!C14 -> 12000000 | D21: =$C$21 -> 12000000 | E21: =$C$21 -> 12000000 | F21: =$C$21 -> 12000000 | G21: =$C$21 -> 12000000 | H21: =$C$21 -> 12000000
B22: Depreciación | D22: =-CIF!C34-'Admón y ventas'!C62 -> -23100000 | E22: =D22-CIF!D34-'Admón y ventas'!D62 -> -46200000 | F22: =E22-CIF!E34-'Admón y ventas'!E62 -> -67300000 | G22: =F22-CIF!F34-'Admón y ventas'!F62 -> -88400000 | H22: =G22-CIF!G34-'Admón y ventas'!G62 -> -99500000 | J22: Valores a partir del presupuesto CIF y gastos de administración y ventas
B23: Propiedad planta y equipo | C23: =SUM(C17:C22) -> 242000000 | D23: =SUM(D17:D22) -> 218900000 | E23: =SUM(E17:E22) -> 195800000 | F23: =SUM(F17:F22) -> 174700000 | G23: =SUM(G17:G22) -> 153600000 | H23: =SUM(H17:H22) -> 142500000 | I23: =+SUM(CIF!C34:G34)+SUM('Admón y ventas'!C62:G62)+SUM(ESF!C22:H22)-(D22+E22+F22+G22) -> 0
B24: Otros activos | C24: 0 | D24: 856329 | E24: 0 | F24: 0 | G24: 0 | H24: 0
B25: Total otros activos | C25: =C24 -> 0 | D25: =D24 -> 856329 | E25: =E24 -> 0 | F25: =F24 -> 0 | G25: =G24 -> 0 | H25: =H24 -> 0
B26: Total activo no corriente | C26: =C23+C25 -> 242000000 | D26: =D23+D25 -> 219756329 | E26: =E23+E25 -> 195800000 | F26: =F23+F25 -> 174700000 | G26: =G23+G25 -> 153600000 | H26: =H23+H25 -> 142500000
B27: Total activos | C27: =C15+C26 -> 245000000 | D27: =D15+D26 -> 2.5389431e+08 | E27: =E15+E26 -> 2.6780601e+08 | F27: =F15+F26 -> 3.1902493e+08 | G27: =G15+G26 -> 4.0614642e+08 | H27: =H15+H26 -> 5.4323923e+08
B29: Pasivo
B30: Pasivo corriente
B31: Proveedores | C31: 0 | D31: ='Ppto Producción'!C70/12 -> 2627657.3 | E31: ='Ppto Producción'!D70/12 -> 2967119.7 | F31: ='Ppto Producción'!E70/12 -> 3384515.4 | G31: ='Ppto Producción'!F70/12 -> 3856909.2 | H31: ='Ppto Producción'!G70/12 -> 4390955.1 | J31: Valores tomados del presupuesto de producción
B32: Impuesto por pagar | C32: 0 | D32: 0 | E32: =ER!C17 -> 2143671 | F32: =ER!D17 -> 10903707 | G32: =ER!E17 -> 26585398 | H32: =ER!F17 -> 44472100 | J32: Valores tomados del estado de resultados
B33: Pasivos laborales | C33: 0 | D33: =+FC!E47 -> 17710490 | E33: =+FC!F47 -> 18401199 | F33: =+FC!G47 -> 19082043 | G33: =+FC!H47 -> 19768997 | H33: =SUM(FC!G12:G14,FC!G22:G24) -> 20460912 | J33: Valores a partir del presupuesto de mano de obra, presupuesto de gastos de administración y ventas y flujo de caja
B34: Acreedores varios | C34: 0 | D34: =+FC!E46 -> 2575054.6 | E34: =+FC!F46 -> 2675481.7 | F34: =+FC!G46 -> 2774474.5 | G34: =+FC!H46 -> 2874355.6 | H34: =SUM(FC!G15:G18,FC!G25:G28) -> 2974958
B35: Total pasivo corriente | C35: =SUM(C31:C34) -> 0 | D35: =SUM(D31:D34) -> 22913202 | E35: =SUM(E31:E34) -> 26187471 | F35: =SUM(F31:F34) -> 36144740 | G35: =SUM(G31:G34) -> 53085660 | H35: =SUM(H31:H34) -> 72298926
B36: Pasivo no corriente
B37: Obligaciones financieras | C37: ='Ppto inversión y plan pagos'!E28 -> 90000000 | D37: ='Ppto inversión y plan pagos'!E29 -> 72000000 | E37: ='Ppto inversión y plan pagos'!E30 -> 54000000 | F37: ='Ppto inversión y plan pagos'!E31 -> 36000000 | G37: ='Ppto inversión y plan pagos'!E32 -> 18000000 | H37: ='Ppto inversión y plan pagos'!E33 -> 0 | J37: Valores tomados de la amortización de préstamos a largo plazo
B38: Obligaciones con socios | C38: 0 | D38: 0 | E38: 8387693.2 | F38: 18276469 | G38: 23865995 | H38: 33397603
B39: Total pasivo no corriente | C39: =SUM(C37:C38) -> 90000000 | D39: =SUM(D37:D38) -> 72000000 | E39: =SUM(E37:E38) -> 62387693 | F39: =SUM(F37:F38) -> 54276469 | G39: =SUM(G37:G38) -> 41865995 | H39: =SUM(H37:H38) -> 33397603
B40: Total pasivo | C40: =C35+C39 -> 90000000 | D40: =D35+D39 -> 94913202 | E40: =E35+E39 -> 88575165 | F40: =F35+F39 -> 90421209 | G40: =G35+G39 -> 94951655 | H40: =H35+H39 -> 1.0569653e+08
B42: Patrimonio
B43: Capital | C43: =C5 -> 155000000 | D43: =C43 -> 155000000 | E43: =D43 -> 155000000 | F43: =E43 -> 155000000 | G43: =F43 -> 155000000 | H43: =G43 -> 155000000
B44: Reservas | C44: 0 | D44: =ER!C19 -> 398110.34 | E44: =D44+ER!D19 -> 2423084.4 | F44: =E44+ER!E19 -> 7360372.6 | G44: =F44+ER!F19 -> 15619477 | H44: =G44+ER!G19 -> 28254270 | J44: Valores a partir del estado de resultados
B45: Utilidades acumuladas | C45: 0 | D45: 0 | E45: =D46 -> 3582993 | F45: =E45+E46 -> 21807760 | G45: =F45+F46 -> 66243353 | H45: =G45+G46 -> 1.4057529e+08 | I45: =+H44-SUM(ER!C19:G19) -> 0
B46: Utilidades del ejercicio | C46: 0 | D46: =ER!C20 -> 3582993 | E46: =ER!D20 -> 18224767 | F46: =ER!E20 -> 44435594 | G46: =ER!F20 -> 74331939 | H46: =ER!G20 -> 1.1371314e+08 | J46: Valores tomados del estado de resultados
...

Sheet Listado completo de archivos 
A6: ESTE ES EL LISTADO COMPLETO DE LAS HERRAMIENTAS PUBLICADAS
A7: Fecha de actualización: enero 30 de 2025
A8: Haz clic aquí para ver una versión actualizada de este listado
A9: IDEA: | B9: Si quieres buscar una herramienta en especial en este listado, dale "Buscar" en Excel (Ctrl + B, en casi todos lados).
B11: Liquidador de sanción por no consignar las cesantías y no pagar los intereses
B13: Liquidador de cesantías y sus intereses aplicado a 11 casos prácticos
B15: [Guía] Clasificación de las personas jurídicas frente al impuesto de renta y el SIMPLE AG 2024
B17: Liquidador y caso práctico para calcular y contabilizar horas extra y recargos durante la reducción de la jornada laboral en 2025 a 46 horas semanales
B19: Liquidador de horas extra diurnas, nocturnas, dominicales y festivas
B21: Liquidadores de sanción por no declarar
B23: Liquidador de aportes a seguridad social de independientes bajo el esquema de presunción de costos (Resolución UGPP 532 de 2024)
B25: Liquidador automatizado de intereses a las cesantías y su comprobante de pago
B27: Liquidador de aportes a seguridad social para independientes con contrato de prestación de servicios
B29: Liquidador de aportes a seguridad social de independientes por cuenta propia y con contrato diferente al de prestación de servicios (vigente hasta el 31 de mayo de 2025)
B31: Histórico del índice de precios al consumidor –IPC–
B33: Modelo en Excel del certificado anual a socios y/o accionistas AG 2024
... B4923: [Liquidador] Modelo para elaborar un Resumen de Ajustes propuestos a los Estados Financieros en el desarrollo de una auditoría externa o Revisoría Fiscal
